[2024-01-29T00:56:44.939+0100] {taskinstance.py:1957} INFO - Dependencies all met for dep_context=non-requeueable deps ti=<TaskInstance: match_id_dag.trigger_match_histories_dag manual__2024-01-28T23:56:29.030954+00:00 [queued]>
[2024-01-29T00:56:44.952+0100] {taskinstance.py:1957} INFO - Dependencies all met for dep_context=requeueable deps ti=<TaskInstance: match_id_dag.trigger_match_histories_dag manual__2024-01-28T23:56:29.030954+00:00 [queued]>
[2024-01-29T00:56:44.956+0100] {taskinstance.py:2171} INFO - Starting attempt 1 of 1
[2024-01-29T00:56:44.980+0100] {taskinstance.py:2192} INFO - Executing <Task(TriggerDagRunOperator): trigger_match_histories_dag> on 2024-01-28 23:56:29.030954+00:00
[2024-01-29T00:56:44.984+0100] {standard_task_runner.py:60} INFO - Started process 17306 to run task
[2024-01-29T00:56:44.986+0100] {standard_task_runner.py:87} INFO - Running: ['airflow', 'tasks', 'run', 'match_id_dag', 'trigger_match_histories_dag', 'manual__2024-01-28T23:56:29.030954+00:00', '--job-id', '31', '--raw', '--subdir', 'DAGS_FOLDER/match_id_dag.py', '--cfg-path', '/tmp/tmphsncagaf']
[2024-01-29T00:56:44.988+0100] {standard_task_runner.py:88} INFO - Job 31: Subtask trigger_match_histories_dag
[2024-01-29T00:56:45.018+0100] {task_command.py:423} INFO - Running <TaskInstance: match_id_dag.trigger_match_histories_dag manual__2024-01-28T23:56:29.030954+00:00 [running]> on host ubuntu.ubuntu.virtualbox.org
[2024-01-29T00:56:45.067+0100] {taskinstance.py:2481} INFO - Exporting env vars: AIRFLOW_CTX_DAG_EMAIL='irachide1@gmail.com' AIRFLOW_CTX_DAG_OWNER='hadoop' AIRFLOW_CTX_DAG_ID='match_id_dag' AIRFLOW_CTX_TASK_ID='trigger_match_histories_dag' AIRFLOW_CTX_EXECUTION_DATE='2024-01-28T23:56:29.030954+00:00' AIRFLOW_CTX_TRY_NUMBER='1' AIRFLOW_CTX_DAG_RUN_ID='manual__2024-01-28T23:56:29.030954+00:00'
[2024-01-29T00:56:45.075+0100] {taskinstance.py:2699} ERROR - Task failed with exception
Traceback (most recent call last):
  File "/home/hadoop/.local/lib/python3.10/site-packages/airflow/models/taskinstance.py", line 433, in _execute_task
    result = execute_callable(context=context, **execute_callable_kwargs)
  File "/home/hadoop/.local/lib/python3.10/site-packages/airflow/operators/trigger_dagrun.py", line 165, in execute
    dag_run = trigger_dag(
  File "/home/hadoop/.local/lib/python3.10/site-packages/airflow/api/common/trigger_dag.py", line 125, in trigger_dag
    triggers = _trigger_dag(
  File "/home/hadoop/.local/lib/python3.10/site-packages/airflow/api/common/trigger_dag.py", line 68, in _trigger_dag
    raise ValueError(
ValueError: The execution_date [2024-01-28T23:56:45.068171+00:00] should be >= start_date [2024-01-29T00:00:00+00:00] from DAG's default_args
[2024-01-29T00:56:45.078+0100] {taskinstance.py:1138} INFO - Marking task as FAILED. dag_id=match_id_dag, task_id=trigger_match_histories_dag, execution_date=20240128T235629, start_date=20240128T235644, end_date=20240128T235645
[2024-01-29T00:56:45.090+0100] {standard_task_runner.py:107} ERROR - Failed to execute job 31 for task trigger_match_histories_dag (The execution_date [2024-01-28T23:56:45.068171+00:00] should be >= start_date [2024-01-29T00:00:00+00:00] from DAG's default_args; 17306)
[2024-01-29T00:56:45.132+0100] {local_task_job_runner.py:234} INFO - Task exited with return code 1
[2024-01-29T00:56:45.139+0100] {taskinstance.py:3281} INFO - 0 downstream tasks scheduled from follow-on schedule check
