[2024-01-28T13:18:18.755+0100] {taskinstance.py:1957} INFO - Dependencies all met for dep_context=non-requeueable deps ti=<TaskInstance: summoner_id_dag.fetch_summoner_ids manual__2024-01-28T12:18:08.386977+00:00 [queued]>
[2024-01-28T13:18:18.759+0100] {taskinstance.py:1957} INFO - Dependencies all met for dep_context=requeueable deps ti=<TaskInstance: summoner_id_dag.fetch_summoner_ids manual__2024-01-28T12:18:08.386977+00:00 [queued]>
[2024-01-28T13:18:18.760+0100] {taskinstance.py:2171} INFO - Starting attempt 1 of 2
[2024-01-28T13:18:18.780+0100] {taskinstance.py:2192} INFO - Executing <Task(BashOperator): fetch_summoner_ids> on 2024-01-28 12:18:08.386977+00:00
[2024-01-28T13:18:18.784+0100] {standard_task_runner.py:60} INFO - Started process 6212 to run task
[2024-01-28T13:18:18.787+0100] {standard_task_runner.py:87} INFO - Running: ['airflow', 'tasks', 'run', 'summoner_id_dag', 'fetch_summoner_ids', 'manual__2024-01-28T12:18:08.386977+00:00', '--job-id', '4', '--raw', '--subdir', 'DAGS_FOLDER/summoner_id_dag.py', '--cfg-path', '/tmp/tmpahryjv1f']
[2024-01-28T13:18:18.789+0100] {standard_task_runner.py:88} INFO - Job 4: Subtask fetch_summoner_ids
[2024-01-28T13:18:18.823+0100] {task_command.py:423} INFO - Running <TaskInstance: summoner_id_dag.fetch_summoner_ids manual__2024-01-28T12:18:08.386977+00:00 [running]> on host ubuntu.ubuntu.virtualbox.org
[2024-01-28T13:18:18.891+0100] {taskinstance.py:2481} INFO - Exporting env vars: AIRFLOW_CTX_DAG_EMAIL='nekruzk@3il.fr' AIRFLOW_CTX_DAG_OWNER='hadoop' AIRFLOW_CTX_DAG_ID='summoner_id_dag' AIRFLOW_CTX_TASK_ID='fetch_summoner_ids' AIRFLOW_CTX_EXECUTION_DATE='2024-01-28T12:18:08.386977+00:00' AIRFLOW_CTX_TRY_NUMBER='1' AIRFLOW_CTX_DAG_RUN_ID='manual__2024-01-28T12:18:08.386977+00:00'
[2024-01-28T13:18:18.893+0100] {subprocess.py:63} INFO - Tmp dir root location: /tmp
[2024-01-28T13:18:18.893+0100] {subprocess.py:75} INFO - Running command: ['/usr/bin/bash', '-c', 'python3 /home/hadoop/Desktop/projectBD/scripts/fetch_summoner_ids.py ']
[2024-01-28T13:18:18.902+0100] {subprocess.py:86} INFO - Output:
[2024-01-28T13:18:20.716+0100] {subprocess.py:93} INFO - put: Your endpoint configuration is wrong; For more details see:  http://wiki.apache.org/hadoop/UnsetHostnameOrPort
[2024-01-28T13:18:21.135+0100] {subprocess.py:97} INFO - Command exited with return code 0
[2024-01-28T13:18:21.163+0100] {taskinstance.py:1138} INFO - Marking task as SUCCESS. dag_id=summoner_id_dag, task_id=fetch_summoner_ids, execution_date=20240128T121808, start_date=20240128T121818, end_date=20240128T121821
[2024-01-28T13:18:21.218+0100] {local_task_job_runner.py:234} INFO - Task exited with return code 0
[2024-01-28T13:18:21.228+0100] {taskinstance.py:3281} INFO - 0 downstream tasks scheduled from follow-on schedule check
