[2024-01-29T00:02:08.109+0100] {taskinstance.py:1957} INFO - Dependencies all met for dep_context=non-requeueable deps ti=<TaskInstance: summoner_id_dag.fetch_summoner_ids manual__2024-01-28T23:02:05.138338+00:00 [queued]>
[2024-01-29T00:02:08.112+0100] {taskinstance.py:1957} INFO - Dependencies all met for dep_context=requeueable deps ti=<TaskInstance: summoner_id_dag.fetch_summoner_ids manual__2024-01-28T23:02:05.138338+00:00 [queued]>
[2024-01-29T00:02:08.113+0100] {taskinstance.py:2171} INFO - Starting attempt 1 of 1
[2024-01-29T00:02:08.128+0100] {taskinstance.py:2192} INFO - Executing <Task(BashOperator): fetch_summoner_ids> on 2024-01-28 23:02:05.138338+00:00
[2024-01-29T00:02:08.130+0100] {standard_task_runner.py:60} INFO - Started process 12468 to run task
[2024-01-29T00:02:08.133+0100] {standard_task_runner.py:87} INFO - Running: ['airflow', 'tasks', 'run', 'summoner_id_dag', 'fetch_summoner_ids', 'manual__2024-01-28T23:02:05.138338+00:00', '--job-id', '26', '--raw', '--subdir', 'DAGS_FOLDER/summoner_id_dag.py', '--cfg-path', '/tmp/tmpjy7dqr5w']
[2024-01-29T00:02:08.135+0100] {standard_task_runner.py:88} INFO - Job 26: Subtask fetch_summoner_ids
[2024-01-29T00:02:08.162+0100] {task_command.py:423} INFO - Running <TaskInstance: summoner_id_dag.fetch_summoner_ids manual__2024-01-28T23:02:05.138338+00:00 [running]> on host ubuntu.ubuntu.virtualbox.org
[2024-01-29T00:02:08.212+0100] {taskinstance.py:2481} INFO - Exporting env vars: AIRFLOW_CTX_DAG_EMAIL='irachide1@gmail.com' AIRFLOW_CTX_DAG_OWNER='hadoop' AIRFLOW_CTX_DAG_ID='summoner_id_dag' AIRFLOW_CTX_TASK_ID='fetch_summoner_ids' AIRFLOW_CTX_EXECUTION_DATE='2024-01-28T23:02:05.138338+00:00' AIRFLOW_CTX_TRY_NUMBER='1' AIRFLOW_CTX_DAG_RUN_ID='manual__2024-01-28T23:02:05.138338+00:00'
[2024-01-29T00:02:08.212+0100] {subprocess.py:63} INFO - Tmp dir root location: /tmp
[2024-01-29T00:02:08.213+0100] {subprocess.py:75} INFO - Running command: ['/usr/bin/bash', '-c', 'python3 /home/hadoop/Desktop/projectBD/scripts/fetch_summoner_ids.py ']
[2024-01-29T00:02:08.220+0100] {subprocess.py:86} INFO - Output:
[2024-01-29T00:02:11.076+0100] {subprocess.py:93} INFO - API call failed for Tarelcat: Status Code 403, Response {"status":{"message":"Forbidden","status_code":403}}
[2024-01-29T00:02:11.076+0100] {subprocess.py:93} INFO - No data fetched for summoner: Tarelcat
[2024-01-29T00:02:11.077+0100] {subprocess.py:93} INFO - API call failed for Kawozz: Status Code 403, Response {"status":{"message":"Forbidden","status_code":403}}
[2024-01-29T00:02:11.077+0100] {subprocess.py:93} INFO - No data fetched for summoner: Kawozz
[2024-01-29T00:02:11.077+0100] {subprocess.py:93} INFO - API call failed for Saken: Status Code 403, Response {"status":{"message":"Forbidden","status_code":403}}
[2024-01-29T00:02:11.077+0100] {subprocess.py:93} INFO - No data fetched for summoner: Saken
[2024-01-29T00:02:11.077+0100] {subprocess.py:93} INFO - All API calls failed. Exiting script.
[2024-01-29T00:02:11.089+0100] {subprocess.py:97} INFO - Command exited with return code 1
[2024-01-29T00:02:11.103+0100] {taskinstance.py:2699} ERROR - Task failed with exception
Traceback (most recent call last):
  File "/home/hadoop/.local/lib/python3.10/site-packages/airflow/models/taskinstance.py", line 428, in _execute_task
    result = execute_callable(context=context, **execute_callable_kwargs)
  File "/home/hadoop/.local/lib/python3.10/site-packages/airflow/operators/bash.py", line 212, in execute
    raise AirflowException(
airflow.exceptions.AirflowException: Bash command failed. The command returned a non-zero exit code 1.
[2024-01-29T00:02:11.109+0100] {taskinstance.py:1138} INFO - Marking task as FAILED. dag_id=summoner_id_dag, task_id=fetch_summoner_ids, execution_date=20240128T230205, start_date=20240128T230208, end_date=20240128T230211
[2024-01-29T00:02:11.134+0100] {standard_task_runner.py:107} ERROR - Failed to execute job 26 for task fetch_summoner_ids (Bash command failed. The command returned a non-zero exit code 1.; 12468)
[2024-01-29T00:02:11.164+0100] {local_task_job_runner.py:234} INFO - Task exited with return code 1
[2024-01-29T00:02:11.174+0100] {taskinstance.py:3281} INFO - 0 downstream tasks scheduled from follow-on schedule check
